<?xml version="1.0" ?>
<!--
    dg3f_m.urdf
    Licensed under the BSD-3-Clause
    Copyright (c) 2019-2025 Tesollo Inc.
    See LICENSE file for details.

    Reference:
    * https://tesollo.com/dg-3f/
-->

<robot name="dg3f_m">

  <link name="base_link" />

  <joint name="base_joint" type="fixed">
    <origin xyz="0 0 0" rpy="0 0 0" />
    <parent link="base_link" />
    <child link="l_dg_mount" />
  </joint>


  <link name="l_dg_mount">
    <inertial>
      <mass value="0.035" />
    </inertial>
    <visual>
      <geometry>
        <mesh filename="file://$(find dg_description)/meshes/dg3f_m/visual/l_dg_mount.dae"/>
      </geometry>
    </visual>
    <collision>
      <geometry>
        <mesh filename="file://$(find dg_description)/meshes/dg3f_m/collision/l_dg_mount_c.STL"/>
      </geometry>
    </collision>
  </link>
  <link name="l_dg_base">
    <inertial>
      <origin xyz="0.00043337 0.00027389 0.044909" rpy="0 0 0" />
      <mass value="0.451" />
      <inertia ixx="0.00074905" ixy="1.3406E-06" ixz="6.2559E-06" iyy="0.00076541" iyz="3.8906E-06" izz="0.00042544" />
    </inertial>
    <visual>
      <origin xyz="0 0 0" rpy="0 0 0" />
      <geometry>
        <mesh filename="file://$(find dg_description)/meshes/dg3f_m/visual/l_dg_base.dae" />
      </geometry>
    </visual>
    <collision>
      <origin xyz="0 0 0" rpy="0 0 0" />
      <geometry>
        <mesh filename="file://$(find dg_description)/meshes/dg3f_m/collision/l_dg_base_c.STL" />
      </geometry>
    </collision>
  </link>
  <joint name="j_dg_dg_base" type="fixed">
    <parent link="l_dg_mount"/>
    <child link="l_dg_base"/>
    <origin rpy="0 0 0" xyz="0 0 0.004"/>
  </joint>
<!--finger1-->
<link name="l_dg_1_1">
    <inertial>
      <origin xyz="0.0039774 -8.829E-09 0.020057" rpy="0 0 0" />
      <mass value="0.0493" />
      <inertia ixx="1.3247E-05" ixy="1.7768E-12" ixz="2.91E-06" iyy="1.5031E-05" iyz="-6.8008E-12" izz="4.5216E-06" />
    </inertial>
    <visual>
      <origin xyz="0 0 0" rpy="0 0 0" />
      <geometry>
        <mesh filename="file://$(find dg_description)/meshes/dg3f_m/visual/l_1_1.dae" />
      </geometry>
    </visual>
    <collision>
      <origin xyz="0 0 0" rpy="0 0 0" />
      <geometry>
        <mesh filename="file://$(find dg_description)/meshes/dg3f_m/collision/l_1_1_c.STL" />
      </geometry>
    </collision>
  </link>
  <joint name="j_dg_1_1" type="revolute">
    <origin xyz="0.026558 0 0.0712" rpy="0 0 0" />
    <parent link="l_dg_base" />
    <child link="l_dg_1_1" />
    <axis xyz="0 0 1" />
    <limit lower="-1.5707963267948966" upper="1.5707963267948966" effort="7.644" velocity="3.141592653589793" />
  </joint>

  <link name="l_dg_1_2">
    <inertial>
      <origin xyz="0.013085 -0.00032847 0.013274" rpy="0 0 0" />
      <mass value="0.0191" />
      <inertia ixx="2.4921E-06" ixy="1.1229E-07" ixz="-1.0064E-06" iyy="6.5468E-06" iyz="1.5916E-07" izz="6.2269E-06" />
    </inertial>
    <visual>
      <origin xyz="0 0 0" rpy="0 0 0" />
      <geometry>
        <mesh filename="file://$(find dg_description)/meshes/dg3f_m/visual/l_1_2.dae" />
      </geometry>
    </visual>
    <collision>
      <origin xyz="0 0 0" rpy="0 0 0" />
      <geometry>
        <mesh filename="file://$(find dg_description)/meshes/dg3f_m/collision/l_1_2_c.STL" />
      </geometry>
    </collision>
  </link>
  <joint name="j_dg_1_2" type="revolute">
    <origin xyz="0 0 0.0405" rpy="0 0 0" />
    <parent link="l_dg_1_1" />
    <child link="l_dg_1_2" />
    <axis xyz="1 0 0" />
    <limit lower="-1.5707963267948966" upper="1.5707963267948966" effort="7.644" velocity="3.141592653589793" />
  </joint>

  <link name="l_dg_1_3">
    <inertial>
      <origin xyz="0.015926 -0.0001838 -1.5688E-05" rpy="0 0 0" />
      <mass value="0.04535" />
      <inertia ixx="2.7201E-06" ixy="5.68E-07" ixz="1.3288E-08" iyy="7.7224E-06" iyz="-3.8255E-11" izz="8.3935E-06" />
    </inertial>
    <visual>
      <origin xyz="0 0 0" rpy="0 0 0" />
      <geometry>
        <mesh filename="file://$(find dg_description)/meshes/dg3f_m/visual/l_1_3.dae" />
      </geometry>
    </visual>
    <collision>
      <origin xyz="0 0 0" rpy="0 0 0" />
      <geometry>
        <mesh filename="file://$(find dg_description)/meshes/dg3f_m/collision/l_1_3_c.STL" />
      </geometry>
    </collision>
  </link>
  <joint name="j_dg_1_3" type="revolute">
    <origin xyz="0.0242 0 0.029" rpy="0 0 0" />
    <parent link="l_dg_1_2" />
    <child link="l_dg_1_3" />
    <axis xyz="0 -1 0" />
    <limit lower="-0.0" upper="2.8099800957108707" effort="7.644" velocity="3.141592653589793" />
  </joint>

  <link name="l_dg_1_4">
    <inertial>
      <origin xyz="0.013887 0.00026201 -4.6519E-10" rpy="0 0 0" />
      <mass value="0.0408" />
      <inertia ixx="2.3785E-06" ixy="7.7437E-08" ixz="-4.9155E-14" iyy="3.5656E-06" iyz="1.1628E-12" izz="3.8056E-06" />
    </inertial>
    <visual>
      <origin xyz="0 0 0" rpy="0 0 0" />
      <geometry>
        <mesh filename="file://$(find dg_description)/meshes/dg3f_m/visual/l_1_4.dae" />
      </geometry>
    </visual>
    <collision>
      <origin xyz="0 0 0" rpy="0 0 0" />
      <geometry>
        <mesh filename="file://$(find dg_description)/meshes/dg3f_m/collision/l_1_4_c.STL" />
      </geometry>
    </collision>
  </link>
  <joint name="j_dg_1_4" type="revolute">
    <origin xyz="0.0434 0 0" rpy="0 0 0" />
    <parent link="l_dg_1_3" />
    <child link="l_dg_1_4" />
    <axis xyz="0 -1 0" />
    <limit lower="-1.5707963267948966" upper="1.8675022996339325" effort="7.644" velocity="3.141592653589793" />
  </joint>

  <link name="l_dg_1_tip">
    <inertial>
      <origin xyz="0.010984 -8.1442E-09 -0.00048894" rpy="0 0 0" />
      <mass value="0.0172" />
      <inertia ixx="1.1855E-06" ixy="5.5892E-12" ixz="9.3654E-08" iyy="1.439E-06" iyz="-1.6025E-11" izz="1.6355E-06" />
    </inertial>
    <visual>
      <origin xyz="0 0 0" rpy="0 0 0" />
      <geometry>
        <mesh filename="file://$(find dg_description)/meshes/dg3f_m/visual/l_1_tip.dae" />
      </geometry>
    </visual>
    <collision>
      <origin xyz="0 0 0" rpy="0 0 0" />
      <geometry>
        <mesh filename="file://$(find dg_description)/meshes/dg3f_m/collision/l_1_tip_c.STL" />
      </geometry>
    </collision>
  </link>
  <joint name="j_dg_1_tip" type="fixed">
    <origin xyz="0.0313 0 0" rpy="0 0 0" />
    <parent link="l_dg_1_4" />
    <child link="l_dg_1_tip" />
  </joint>
  <!--finger2-->
  <link name="l_dg_2_1">
    <inertial>
      <origin xyz="-0.0039774 8.829E-09 0.020057" rpy="0 0 0" />
      <mass value="0.0493" />
      <inertia ixx="1.3247E-05" ixy="1.7768E-12" ixz="-2.91E-06" iyy="1.5031E-05" iyz="6.8008E-12" izz="4.5216E-06" />
    </inertial>
    <visual>
      <origin xyz="0 0 0" rpy="0 0 0" />
      <geometry>
        <mesh filename="file://$(find dg_description)/meshes/dg3f_m/visual/l_23_1.dae" />
      </geometry>
    </visual>
    <collision>
      <origin xyz="0 0 0" rpy="0 0 0" />
      <geometry>
        <mesh filename="file://$(find dg_description)/meshes/dg3f_m/collision/l_23_1_c.STL" />
      </geometry>
    </collision>
  </link>
  <joint name="j_dg_2_1" type="revolute">
    <origin xyz="-0.013279 0.023 0.0712" rpy="0 0 0" />
    <parent link="l_dg_base" />
    <child link="l_dg_2_1" />
    <axis xyz="0 0 1" />
    <limit lower="-2.129301687433082" upper="1.5707963267948966" effort="7.644" velocity="3.141592653589793" />
  </joint>

  <link name="l_dg_2_2">
    <inertial>
      <origin xyz="-0.013085 0.00032847 0.013274" rpy="0 0 0" />
      <mass value="0.0191" />
      <inertia ixx="2.4921E-06" ixy="1.1229E-07" ixz="1.0064E-06" iyy="6.5468E-06" iyz="-1.5916E-07" izz="6.2269E-06" />
    </inertial>
    <visual>
      <origin xyz="0 0 0" rpy="0 0 0" />
      <geometry>
        <mesh filename="file://$(find dg_description)/meshes/dg3f_m/visual/l_23_2.dae" />
      </geometry>
    </visual>
    <collision>
      <origin xyz="0 0 0" rpy="0 0 0" />
      <geometry>
        <mesh filename="file://$(find dg_description)/meshes/dg3f_m/collision/l_23_2_c.STL" />
      </geometry>
    </collision>
  </link>
  <joint name="j_dg_2_2" type="revolute">
    <origin xyz="0 0 0.0405" rpy="0 0 0" />
    <parent link="l_dg_2_1" />
    <child link="l_dg_2_2" />
    <axis xyz="-1 0 0" />
    <limit lower="-1.5707963267948966" upper="1.5707963267948966" effort="7.644" velocity="3.141592653589793" />
  </joint>

  <link name="l_dg_2_3">
    <inertial>
      <origin xyz="-0.0159258962872331 0.000183796044363631 -1.56883420763254E-05" rpy="0 0 0" />
      <mass value="0.04535" />
      <inertia ixx="2.72014634088682E-06" ixy="5.67998480575708E-07" ixz="-1.32884157040829E-08" iyy="7.72244376203872E-06" iyz="3.82553595666275E-11" izz="8.39345564298784E-06" />   
    </inertial>
    <visual>
      <origin xyz="0 0 0" rpy="0 0 0" />
      <geometry>
        <mesh filename="file://$(find dg_description)/meshes/dg3f_m/visual/l_23_3.dae" />
      </geometry>
    </visual>
    <collision>
      <origin xyz="0 0 0" rpy="0 0 0" />
      <geometry>
        <mesh filename="file://$(find dg_description)/meshes/dg3f_m/collision/l_23_3_c.STL" />
      </geometry>
    </collision>
  </link>
  <joint name="j_dg_2_3" type="revolute">
    <origin xyz="-0.0242 0 0.029" rpy="0 0 0" />
    <parent link="l_dg_2_2" />
    <child link="l_dg_2_3" />
    <axis xyz="0 1 0" />
    <limit lower="-0.0" upper="2.8099800957108707" effort="7.644" velocity="3.141592653589793" />
  </joint>

  <link name="l_dg_2_4">
    <inertial>
      <origin xyz="-0.013887 -0.00026201 -4.6519E-10" rpy="0 0 0" />
      <mass value="0.0408" />
      <inertia ixx="2.3785E-06" ixy="7.7437E-08" ixz="4.9155E-14" iyy="3.5656E-06" iyz="-1.1628E-12" izz="3.8056E-06" />    
    </inertial>
    <visual>
      <origin xyz="0 0 0" rpy="0 0 0" />
      <geometry>
        <mesh filename="file://$(find dg_description)/meshes/dg3f_m/visual/l_23_4.dae" />
      </geometry>
    </visual>
    <collision>
      <origin xyz="0 0 0" rpy="0 0 0" />
      <geometry>
        <mesh filename="file://$(find dg_description)/meshes/dg3f_m/collision/l_23_4_c.STL" />
      </geometry>
    </collision>
  </link>
  <joint name="j_dg_2_4" type="revolute">
    <origin xyz="-0.0434 0 0" rpy="0 0 0" />
    <parent link="l_dg_2_3" />
    <child link="l_dg_2_4" />
    <axis xyz="0 1 0" />
    <limit lower="-1.5707963267948966" upper="1.8675022996339325" effort="7.644" velocity="3.141592653589793" />
  </joint>

  <link name="l_dg_2_tip">
    <inertial>
      <origin xyz="-0.010984 -1.7412E-08 -0.00048893" rpy="0 0 0" />
      <mass value="0.0172" />
      <inertia ixx="1.1855E-06" ixy="-2.6029E-12" ixz="-9.3657E-08" iyy="1.439E-06" iyz="1.8278E-11" izz="1.6355E-06" />    
    </inertial>
    <visual>
      <origin xyz="0 0 0" rpy="0 0 0" />
      <geometry>
        <mesh filename="file://$(find dg_description)/meshes/dg3f_m/visual/l_23_tip.dae" />
      </geometry>
    </visual>
    <collision>
      <origin xyz="0 0 0" rpy="0 0 0" />
      <geometry>
        <mesh filename="file://$(find dg_description)/meshes/dg3f_m/collision/l_23_tip_c.STL" />
      </geometry>
    </collision>
  </link>
  <joint name="j_dg_2_tip" type="fixed">
    <origin xyz="-0.0313 0 0" rpy="0 0 0" />
    <parent link="l_dg_2_4" />
    <child link="l_dg_2_tip" />
  </joint>
  <!--finger3-->
  <link name="l_dg_3_1">
    <inertial>
      <origin xyz="-0.0039774 8.829E-09 0.020057" rpy="0 0 0" />
      <mass value="0.0493" />
      <inertia ixx="1.3247E-05" ixy="1.7768E-12" ixz="-2.91E-06" iyy="1.5031E-05" iyz="6.8008E-12" izz="4.5216E-06" />
    </inertial>
    <visual>
      <origin xyz="0 0 0" rpy="0 0 0" />
      <geometry>
        <mesh filename="file://$(find dg_description)/meshes/dg3f_m/visual/l_23_1.dae" />
      </geometry>
    </visual>
    <collision>
      <origin xyz="0 0 0" rpy="0 0 0" />
      <geometry>
        <mesh filename="file://$(find dg_description)/meshes/dg3f_m/collision/l_23_1_c.STL" />
      </geometry>
    </collision>
  </link>
  <joint name="j_dg_3_1" type="revolute">
    <origin xyz="-0.013279 -0.023 0.0712" rpy="0 0 0" />
    <parent link="l_dg_base" />
    <child link="l_dg_3_1" />
    <axis xyz="0 0 1" />
    <limit lower="-1.5707963267948966" upper="2.129301687433082" effort="7.644" velocity="3.141592653589793" />
  </joint>

  <link name="l_dg_3_2">
    <inertial>
      <origin xyz="-0.013085 0.00032847 0.013274" rpy="0 0 0" />
      <mass value="0.0191" />
      <inertia ixx="2.4921E-06" ixy="1.1229E-07" ixz="1.0064E-06" iyy="6.5468E-06" iyz="-1.5916E-07" izz="6.2269E-06" />
    </inertial>
    <visual>
      <origin xyz="0 0 0" rpy="0 0 0" />
      <geometry>
        <mesh filename="file://$(find dg_description)/meshes/dg3f_m/visual/l_23_2.dae" />
      </geometry>
    </visual>
    <collision>
      <origin xyz="0 0 0" rpy="0 0 0" />
      <geometry>
        <mesh filename="file://$(find dg_description)/meshes/dg3f_m/collision/l_23_2_c.STL" />
      </geometry>
    </collision>
  </link>
  <joint name="j_dg_3_2" type="revolute">
    <origin xyz="0 0 0.0405" rpy="0 0 0" />
    <parent link="l_dg_3_1" />
    <child link="l_dg_3_2" />
    <axis xyz="-1 0 0" />
    <limit lower="-1.5707963267948966" upper="1.5707963267948966" effort="7.644" velocity="3.141592653589793" />
  </joint>

  <link name="l_dg_3_3">
    <inertial>
      <origin xyz="-0.0159258962872331 0.000183796044363631 -1.56883420763254E-05" rpy="0 0 0" />
      <mass value="0.04535" />
      <inertia ixx="2.72014634088682E-06" ixy="5.67998480575708E-07" ixz="-1.32884157040829E-08" iyy="7.72244376203872E-06" iyz="3.82553595666275E-11" izz="8.39345564298784E-06" />   
    </inertial>
    <visual>
      <origin xyz="0 0 0" rpy="0 0 0" />
      <geometry>
        <mesh filename="file://$(find dg_description)/meshes/dg3f_m/visual/l_23_3.dae" />
      </geometry>
    </visual>
    <collision>
      <origin xyz="0 0 0" rpy="0 0 0" />
      <geometry>
        <mesh filename="file://$(find dg_description)/meshes/dg3f_m/collision/l_23_3_c.STL" />
      </geometry>
    </collision>
  </link>
  <joint name="j_dg_3_3" type="revolute">
    <origin xyz="-0.0242 0 0.029" rpy="0 0 0" />
    <parent link="l_dg_3_2" />
    <child link="l_dg_3_3" />
    <axis xyz="0 1 0" />
    <limit lower="-0.0" upper="2.8099800957108707" effort="7.644" velocity="3.141592653589793" />
  </joint>

  <link name="l_dg_3_4">
    <inertial>
      <origin xyz="-0.013887 -0.00026201 -4.6519E-10" rpy="0 0 0" />
      <mass value="0.0408" />
      <inertia ixx="2.3785E-06" ixy="7.7437E-08" ixz="4.9155E-14" iyy="3.5656E-06" iyz="-1.1628E-12" izz="3.8056E-06" />    
    </inertial>
    <visual>
      <origin xyz="0 0 0" rpy="0 0 0" />
      <geometry>
        <mesh filename="file://$(find dg_description)/meshes/dg3f_m/visual/l_23_4.dae" />
      </geometry>
    </visual>
    <collision>
      <origin xyz="0 0 0" rpy="0 0 0" />
      <geometry>
        <mesh filename="file://$(find dg_description)/meshes/dg3f_m/collision/l_23_4_c.STL" />
      </geometry>
    </collision>
  </link>
  <joint name="j_dg_3_4" type="revolute">
    <origin xyz="-0.0434 0 0" rpy="0 0 0" />
    <parent link="l_dg_3_3" />
    <child link="l_dg_3_4" />
    <axis xyz="0 1 0" />
    <limit lower="-1.5707963267948966" upper="1.8675022996339325" effort="7.644" velocity="3.141592653589793" />
  </joint>

  <link name="l_dg_3_tip">
    <inertial>
      <origin xyz="-0.010984 -1.7412E-08 -0.00048893" rpy="0 0 0" />
      <mass value="0.0172" />
      <inertia ixx="1.1855E-06" ixy="-2.6029E-12" ixz="-9.3657E-08" iyy="1.439E-06" iyz="1.8278E-11" izz="1.6355E-06" />    
    </inertial>
    <visual>
      <origin xyz="0 0 0" rpy="0 0 0" />
      <geometry>
        <mesh filename="file://$(find dg_description)/meshes/dg3f_m/visual/l_23_tip.dae" />
      </geometry>
    </visual>
    <collision>
      <origin xyz="0 0 0" rpy="0 0 0" />
      <geometry>
        <mesh filename="file://$(find dg_description)/meshes/dg3f_m/collision/l_23_tip_c.STL" />
      </geometry>
    </collision>
  </link>
  <joint name="j_dg_3_tip" type="fixed">
    <origin xyz="-0.0313 0 0" rpy="0 0 0" />
    <parent link="l_dg_3_4" />
    <child link="l_dg_3_tip" />
  </joint>
</robot>
